WARNING  kubetest:utils.py:139 got api exception while waiting: (404)
Reason: Not Found
HTTP response headers: HTTPHeaderDict({'Audit-Id': '176d5d9a-e6e7-4182-8166-819bee884659', 'Cache-Control': 'no-cache, private', 'Content-Type': 'application/json', 'X-Kubernetes-Pf-Flowschema-Uid': '430a6917-b519-42d9-8eec-e4ea6cc1b553', 'X-Kubernetes-Pf-Prioritylevel-Uid': '1084d407-571d-4de2-8a2c-65843376bbf4', 'Date': 'Tue, 08 Oct 2024 11:12:06 GMT', 'Content-Length': '208'})
HTTP response body: {"kind":"Status","apiVersion":"v1","metadata":{},"status":"Failure","message":"namespaces \"context-kypros\" not found","reason":"NotFound","details":{"name":"context-kypros","kind":"namespaces"},"code":404}